replay_output/market_data_binance_BTCUSDT_2026-06-07.csv
recv_tsec,recv_tnsec,venue,stream_kind,shard_id,conn_epoch,conn_seq,symbol,payload_json
1780792020|24613000|binance|depth|0|0|0|BTCUSDT|"""{""lastUpdateId"":95220197983,""bids"":[[""60826.92000000"",""0.15953000""],[""60826.91000000"",""0.00081000""],[""60826.68000000"",""0.00009000""],[""60826.64000000"",""0.00675000""],[""60826.63000000"",""0.00589000""]],""asks"":[[""60826.93000000"",""4.41726000""],[""60826.94000000"",""0.00155000""],[""60826.95000000"",""0.00017000""],[""60828.12000000"",""0.00018000""],[""60828.13000000"",""0.11780000""]]}"""
1780792020|24763000|binance|depth|0|0|1|BTCUSDT|"""{""e"":""depthUpdate"",""E"":1780791932614,""s"":""BTCUSDT"",""U"":95220197971,""u"":95220197983,""b"":[[""60819.46000000"",""0.00000000""],[""60818.90000000"",""0.00910000""],[""54744.23000000"",""0.00500000""],[""48661.54000000"",""0.00000000""]],""a"":[[""60835.50000000"",""0.02400000""],[""60836.10000000"",""0.04000000""],[""60836.71000000"",""0.04000000""],[""60836.75000000"",""0.02000000""],[""60839.85000000"",""0.00000000""],[""60842.29000000"",""0.00000000""],[""60883.71000000"",""0.00000000""]]}"""
1780792020|24770000|binance|depth|0|0|2|BTCUSDT|"""{""e"":""trade"",""E"":1780791932711,""s"":""BTCUSDT"",""t"":6380215105,""p"":""60826.92000000"",""q"":""0.00200000"",""T"":1780791932711,""m"":true,""M"":true}"""
1780792020|24772000|binance|depth|0|0|3|BTCUSDT|"""{""lastUpdateId"":95220198000,""bids"":[[""60826.92000000"",""0.15753000""],[""60826.91000000"",""0.00081000""],[""60826.68000000"",""0.00009000""],[""60826.64000000"",""0.00675000""],[""60826.63000000"",""0.00589000""]],""asks"":[[""60826.93000000"",""4.41726000""],[""60826.94000000"",""0.00155000""],[""60826.95000000"",""0.00017000""],[""60828.12000000"",""0.00018000""],[""60828.13000000"",""0.11780000""]]}"""
1780792020|24781000|binance|depth|0|0|4|BTCUSDT|"""{""e"":""depthUpdate"",""E"":1780791932714,""s"":""BTCUSDT"",""U"":95220197984,""u"":95220198000,""b"":[[""60826.92000000"",""0.15753000""],[""60826.91000000"",""0.00081000""],[""54744.23000000"",""0.00500000""],[""48661.54000000"",""0.00000000""]],""a"":[[""60839.90000000"",""0.00000000""],[""60841.68000000"",""0.00000000""],[""60842.95000000"",""0.00000000""],[""60884.97000000"",""0.00000000""]]}"""
1780792020|24785000|binance|depth|0|0|5|BTCUSDT|"""{""e"":""trade"",""E"":1780791932724,""s"":""BTCUSDT"",""t"":6380215106,""p"":""60826.92000000"",""q"":""0.00044000"",""T"":1780791932724,""m"":true,""M"":true}"""
1780792020|24788000|binance|depth|0|0|6|BTCUSDT|"""{""lastUpdateId"":95220198023,""bids"":[[""60826.92000000"",""0.15499000""],[""60826.91000000"",""0.00081000""],[""60826.68000000"",""0.00009000""],[""60826.64000000"",""0.00675000""],[""60826.63000000"",""0.00589000""]],""asks"":[[""60826.93000000"",""4.41726000""],[""60826.94000000"",""0.00155000""],[""60826.95000000"",""0.00017000""],[""60828.12000000"",""0.00018000""],[""60828.13000000"",""0.11780000""]]}"""
1780792020|24795000|binance|depth|0|0|7|BTCUSDT|"""{""e"":""depthUpdate"",""E"":1780791932814,""s"":""BTCUSDT"",""U"":95220198001,""u"":95220198023,""b"":[[""60826.92000000"",""0.15499000""],[""60825.61000000"",""0.00000000""],[""60825.60000000"",""0.00018000""],[""60822.62000000"",""0.00018000""],[""60822.61000000"",""0.30123000""],[""60818.59000000"",""0.00024000""],[""60808.13000000"",""0.85586000""],[""60806.54000000"",""0.00010000""],[""60800.25000000"",""0.00000000""],[""60798.66000000"",""0.00210000""],[""54744.23000000"",""0.00500000""]],""a"":[[""60842.90000000"",""0.00000000""],[""60847.33000000"",""0.00200000""],[""60848.92000000"",""0.00000000""],[""60892.08000000"",""0.11244000""],[""81537.94000000"",""0.00052000""]]}"""
1780792020|24800000|binance|depth|0|0|8|BTCUSDT|"""{""lastUpdateId"":95220198039,""bids"":[[""60826.92000000"",""0.15490000""],[""60826.91000000"",""0.00081000""],[""60826.68000000"",""0.00009000""],[""60826.64000000"",""0.00675000""],[""60826.63000000"",""0.00589000""]],""asks"":[[""60826.93000000"",""4.41726000""],[""60826.94000000"",""0.00155000""],[""60826.95000000"",""0.00017000""],[""60828.12000000"",""0.00018000""],[""60828.13000000"",""0.11780000""]]}"""
1780792020|24808000|binance|depth|0|0|9|BTCUSDT|"""{""e"":""depthUpdate"",""E"":1780791932914,""s"":""BTCUSDT"",""U"":95220198024,""u"":95220198039,""b"":[[""60826.92000000"",""0.15490000""],[""60826.63000000"",""0.00589000""],[""60825.60000000"",""0.00000000""],[""60822.60000000"",""0.11403000""],[""60818.59000000"",""1.57876000""],[""54744.23000000"",""0.00500000""]],""a"":[[""60848.28000000"",""0.02000000""],[""60883.91000000"",""0.02000000""]]}"""
1780792020|24812000|binance|depth|0|0|10|BTCUSDT|"""{""e"":""trade"",""E"":1780791932943,""s"":""BTCUSDT"",""t"":6380215107,""p"":""60826.92000000"",""q"":""0.00200000"",""T"":1780791932943,""m"":true,""M"":true}"""
1780792020|24828000|binance|depth|0|0|11|BTCUSDT|"""{""lastUpdateId"":95220198049,""bids"":[[""60826.92000000"",""0.15290000""],[""60826.91000000"",""0.00081000""],[""60826.68000000"",""0.00009000""],[""60826.64000000"",""0.00675000""],[""60826.63000000"",""0.00589000""]],""asks"":[[""60826.93000000"",""4.41726000""],[""60826.94000000"",""0.00155000""],[""60826.95000000"",""0.00017000""],[""60828.12000000"",""0.00018000""],[""60828.13000000"",""0.11780000""]]}"""
1780792020|24835000|binance|depth|0|0|12|BTCUSDT|"""{""e"":""depthUpdate"",""E"":1780791933014,""s"":""BTCUSDT"",""U"":95220198040,""u"":95220198049,""b"":[[""60826.92000000"",""0.15290000""],[""54744.23000000"",""0.00500000""],[""48662.00000000"",""0.00000000""],[""48661.54000000"",""0.00041000""]],""a"":[[""60883.91000000"",""0.00000000""],[""85069.31000000"",""0.00057000""]]}"""
1780792020|24839000|binance|depth|0|0|13|BTCUSDT|"""{""lastUpdateId"":95220198066,""bids"":[[""60826.92000000"",""0.15527000""],[""60826.91000000"",""0.00098000""],[""60826.90000000"",""0.00017000""],[""60826.68000000"",""0.00009000""],[""60826.64000000"",""0.00675000""]],""asks"":[[""60826.93000000"",""4.41745000""],[""60826.94000000"",""0.00155000""],[""60826.95000000"",""0.00017000""],[""60828.12000000"",""0.00018000""],[""60828.13000000"",""0.11780000""]]}"""
1780792020|24846000|binance|depth|0|0|14|BTCUSDT|"""{""e"":""depthUpdate"",""E"":1780791933114,""s"":""BTCUSDT"",""U"":95220198050,""u"":95220198066,""b"":[[""60826.92000000"",""0.15527000""],[""60826.91000000"",""0.00098000""],[""60826.90000000"",""0.00017000""],[""60522.79000000"",""0.10000000""],[""60504.63000000"",""0.30000000""],[""60486.47000000"",""0.50000000""],[""54744.23000000"",""0.00500000""]],""a"":[[""60826.93000000"",""4.41745000""]]}"""
1780792020|24849000|binance|depth|0|0|15|BTCUSDT|"""{""e"":""trade"",""E"":1780791933171,""s"":""BTCUSDT"",""t"":6380215108,""p"":""60826.92000000"",""q"":""0.00200000"",""T"":1780791933171,""m"":true,""M"":true}"""
1780792020|24852000|binance|depth|0|0|16|BTCUSDT|"""{""lastUpdateId"":95220198099,""bids"":[[""60826.92000000"",""0.15318000""],[""60826.91000000"",""0.00098000""],[""60826.90000000"",""0.00017000""],[""60826.68000000"",""0.00009000""],[""60826.64000000"",""0.00675000""]],""asks"":[[""60826.93000000"",""4.41745000""],[""60826.94000000"",""0.00155000""],[""60826.95000000"",""0.00017000""],[""60828.12000000"",""0.00018000""],[""60828.13000000"",""0.11780000""]]}"""
1780792020|24859000|binance|depth|0|0|17|BTCUSDT|"""{""e"":""depthUpdate"",""E"":1780791933214,""s"":""BTCUSDT"",""U"":95220198067,""u"":95220198099,""b"":[[""60826.92000000"",""0.15318000""],[""60826.91000000"",""0.00098000""],[""60822.62000000"",""0.00000000""],[""60822.61000000"",""0.00036000""],[""60822.28000000"",""0.00019000""],[""60816.40000000"",""0.00009000""],[""60468.31000000"",""0.70000000""],[""58290.00000000"",""0.13332000""],[""58000.00000000"",""366.52731000""],[""54744.23000000"",""0.00500000""],[""54744.22000000"",""0.00010000""],[""48661.54000000"",""0.00000000""]],""a"":[[""60828.98000000"",""0.15642000""],[""60830.09000000"",""0.00000000""],[""60830.98000000"",""0.00000000""],[""60832.50000000"",""0.00031000""],[""60832.51000000"",""0.00000000""],[""60833.00000000"",""0.10000000""],[""60833.89000000"",""0.00905000""],[""60840.74000000"",""0.00009000""],[""60851.24000000"",""0.30000000""],[""60869.49000000"",""0.50000000""],[""60881.59000000"",""0.58980000""],[""60887.74000000"",""0.70000000""],[""61374.36000000"",""0.00010000""]]}"""
